{
    "Attributes": {
        "Error": "Authentication selected: Basic realm=\"Please enter your Earthdata Login credentials. If you do not have a Earthdata Login, create one at https://urs.earthdata.nasa.gov//users/new\"\nhttps://datapool.asf.alaska.edu/GRD_HD/SA/S1A_IW_GRDH_1SDV_20180409T232311_20180409T232336_021397_024D6D_DA9A.zip:\n2018-09-11 21:53:43 ERROR 404: Not Found.\nTraceback (most recent call last):\n  File \"/mnt/s/seppo/commands/seppo_recipe_processor.py\", line 664, in processing\n    in_files = prepare_working_directory (args,tempdir)\n  File \"/mnt/s/seppo/commands/seppo_recipe_processor.py\", line 414, in prepare_working_directory\n    myfile=get_file(args.input,tempdir)\n  File \"/mnt/s/seppo/commands/seppo_recipe_processor.py\", line 327, in get_file\n    myfile=get_https(d_s,d_t='.')\n  File \"/mnt/s/seppo/commands/seppo_recipe_processor.py\", line 228, in get_https\n    raise RuntimeError('Could not retrieve {}'.format(d_s))\nRuntimeError: Could not retrieve https://datapool.asf.alaska.edu/GRD_HD/SA/S1A_IW_GRDH_1SDV_20180409T232311_20180409T232336_021397_024D6D_DA9A.zip\n\nDuring handling of the above exception, another exception occurred:\n\nTraceback (most recent call last):\n  File \"/mnt/s/seppo/commands/seppo_recipe_processor.py\", line 764, in <module>\n    main()\n  File \"/mnt/s/seppo/commands/seppo_recipe_processor.py\", line 760, in main\n    return processing(args)\n  File \"/mnt/s/seppo/commands/seppo_recipe_processor.py\", line 666, in processing\n    raise RuntimeError(\"Error preparing recipe or input data {}\\n{}\".format(args.recipe,args.input))\nRuntimeError: Error preparing recipe or input data ${SEPPO_HOME}/recipies/gamma/recipe_sentinel1_grd.py -t -r\nhttps://datapool.asf.alaska.edu/GRD_HD/SA/S1A_IW_GRDH_1SDV_20180409T232311_20180409T232336_021397_024D6D_DA9A.zip\n"
    },
    "Duration_hms": "0:00:12.233979",
    "Duration_sec": "12.233979",
    "EndTime": "2018-09-11T21:53:43.433124",
    "Job": "seppo_recipe_processor.py -z -o s3://data.earth/sar/sentinel1/rtc/20.0m -r '${SEPPO_HOME}/recipies/gamma/recipe_sentinel1_grd.py -t -r' -i https://datapool.asf.alaska.edu/GRD_HD/SA/S1A_IW_GRDH_1SDV_20180409T232311_20180409T232336_021397_024D6D_DA9A.zip",
    "JobID": "silviaterra-s1pa",
    "StartTime": "2018-09-11T21:53:31.199145",
    "User": "ebduser"
}
-----------------------------------------------------------
{
    "Attributes": {
        "Error": "Authentication selected: Basic realm=\"Please enter your Earthdata Login credentials. If you do not have a Earthdata Login, create one at https://urs.earthdata.nasa.gov//users/new\"\nhttps://datapool.asf.alaska.edu/GRD_HD/SA/S1A_IW_GRDH_1SDV_20180409T232336_20180409T232401_021397_024D6D_14AA.zip:\n2018-09-11 22:16:19 ERROR 404: Not Found.\nTraceback (most recent call last):\n  File \"/mnt/s/seppo/commands/seppo_recipe_processor.py\", line 664, in processing\n    in_files = prepare_working_directory (args,tempdir)\n  File \"/mnt/s/seppo/commands/seppo_recipe_processor.py\", line 414, in prepare_working_directory\n    myfile=get_file(args.input,tempdir)\n  File \"/mnt/s/seppo/commands/seppo_recipe_processor.py\", line 327, in get_file\n    myfile=get_https(d_s,d_t='.')\n  File \"/mnt/s/seppo/commands/seppo_recipe_processor.py\", line 228, in get_https\n    raise RuntimeError('Could not retrieve {}'.format(d_s))\nRuntimeError: Could not retrieve https://datapool.asf.alaska.edu/GRD_HD/SA/S1A_IW_GRDH_1SDV_20180409T232336_20180409T232401_021397_024D6D_14AA.zip\n\nDuring handling of the above exception, another exception occurred:\n\nTraceback (most recent call last):\n  File \"/mnt/s/seppo/commands/seppo_recipe_processor.py\", line 764, in <module>\n    main()\n  File \"/mnt/s/seppo/commands/seppo_recipe_processor.py\", line 760, in main\n    return processing(args)\n  File \"/mnt/s/seppo/commands/seppo_recipe_processor.py\", line 666, in processing\n    raise RuntimeError(\"Error preparing recipe or input data {}\\n{}\".format(args.recipe,args.input))\nRuntimeError: Error preparing recipe or input data ${SEPPO_HOME}/recipies/gamma/recipe_sentinel1_grd.py -t -r\nhttps://datapool.asf.alaska.edu/GRD_HD/SA/S1A_IW_GRDH_1SDV_20180409T232336_20180409T232401_021397_024D6D_14AA.zip\n"
    },
    "Duration_hms": "0:00:06.644533",
    "Duration_sec": "6.644533",
    "EndTime": "2018-09-11T22:16:19.376759",
    "Job": "seppo_recipe_processor.py -z -o s3://data.earth/sar/sentinel1/rtc/20.0m -r '${SEPPO_HOME}/recipies/gamma/recipe_sentinel1_grd.py -t -r' -i https://datapool.asf.alaska.edu/GRD_HD/SA/S1A_IW_GRDH_1SDV_20180409T232336_20180409T232401_021397_024D6D_14AA.zip",
    "JobID": "silviaterra-s1pa",
    "StartTime": "2018-09-11T22:16:12.732226",
    "User": "ebduser"
}
-----------------------------------------------------------
{
    "Attributes": {
        "Error": "Authentication selected: Basic realm=\"Please enter your Earthdata Login credentials. If you do not have a Earthdata Login, create one at https://urs.earthdata.nasa.gov//users/new\"\nhttps://datapool.asf.alaska.edu/GRD_HD/SA/S1A_IW_GRDH_1SDV_20180409T232401_20180409T232426_021397_024D6D_B769.zip:\n2018-09-11 22:16:27 ERROR 404: Not Found.\nTraceback (most recent call last):\n  File \"/mnt/s/seppo/commands/seppo_recipe_processor.py\", line 664, in processing\n    in_files = prepare_working_directory (args,tempdir)\n  File \"/mnt/s/seppo/commands/seppo_recipe_processor.py\", line 414, in prepare_working_directory\n    myfile=get_file(args.input,tempdir)\n  File \"/mnt/s/seppo/commands/seppo_recipe_processor.py\", line 327, in get_file\n    myfile=get_https(d_s,d_t='.')\n  File \"/mnt/s/seppo/commands/seppo_recipe_processor.py\", line 228, in get_https\n    raise RuntimeError('Could not retrieve {}'.format(d_s))\nRuntimeError: Could not retrieve https://datapool.asf.alaska.edu/GRD_HD/SA/S1A_IW_GRDH_1SDV_20180409T232401_20180409T232426_021397_024D6D_B769.zip\n\nDuring handling of the above exception, another exception occurred:\n\nTraceback (most recent call last):\n  File \"/mnt/s/seppo/commands/seppo_recipe_processor.py\", line 764, in <module>\n    main()\n  File \"/mnt/s/seppo/commands/seppo_recipe_processor.py\", line 760, in main\n    return processing(args)\n  File \"/mnt/s/seppo/commands/seppo_recipe_processor.py\", line 666, in processing\n    raise RuntimeError(\"Error preparing recipe or input data {}\\n{}\".format(args.recipe,args.input))\nRuntimeError: Error preparing recipe or input data ${SEPPO_HOME}/recipies/gamma/recipe_sentinel1_grd.py -t -r\nhttps://datapool.asf.alaska.edu/GRD_HD/SA/S1A_IW_GRDH_1SDV_20180409T232401_20180409T232426_021397_024D6D_B769.zip\n"
    },
    "Duration_hms": "0:00:07.330853",
    "Duration_sec": "7.330853",
    "EndTime": "2018-09-11T22:16:27.785503",
    "Job": "seppo_recipe_processor.py -z -o s3://data.earth/sar/sentinel1/rtc/20.0m -r '${SEPPO_HOME}/recipies/gamma/recipe_sentinel1_grd.py -t -r' -i https://datapool.asf.alaska.edu/GRD_HD/SA/S1A_IW_GRDH_1SDV_20180409T232401_20180409T232426_021397_024D6D_B769.zip",
    "JobID": "silviaterra-s1pa",
    "StartTime": "2018-09-11T22:16:20.454650",
    "User": "ebduser"
}
-----------------------------------------------------------
{
    "Attributes": {
        "Error": "Authentication selected: Basic realm=\"Please enter your Earthdata Login credentials. If you do not have a Earthdata Login, create one at https://urs.earthdata.nasa.gov//users/new\"\nhttps://datapool.asf.alaska.edu/GRD_HD/SA/S1A_IW_GRDH_1SDV_20180409T232311_20180409T232336_021397_024D6D_DA9A.zip:\n2018-09-11 22:17:18 ERROR 404: Not Found.\nTraceback (most recent call last):\n  File \"/mnt/s/seppo/commands/seppo_recipe_processor.py\", line 664, in processing\n    in_files = prepare_working_directory (args,tempdir)\n  File \"/mnt/s/seppo/commands/seppo_recipe_processor.py\", line 414, in prepare_working_directory\n    myfile=get_file(args.input,tempdir)\n  File \"/mnt/s/seppo/commands/seppo_recipe_processor.py\", line 327, in get_file\n    myfile=get_https(d_s,d_t='.')\n  File \"/mnt/s/seppo/commands/seppo_recipe_processor.py\", line 228, in get_https\n    raise RuntimeError('Could not retrieve {}'.format(d_s))\nRuntimeError: Could not retrieve https://datapool.asf.alaska.edu/GRD_HD/SA/S1A_IW_GRDH_1SDV_20180409T232311_20180409T232336_021397_024D6D_DA9A.zip\n\nDuring handling of the above exception, another exception occurred:\n\nTraceback (most recent call last):\n  File \"/mnt/s/seppo/commands/seppo_recipe_processor.py\", line 764, in <module>\n    main()\n  File \"/mnt/s/seppo/commands/seppo_recipe_processor.py\", line 760, in main\n    return processing(args)\n  File \"/mnt/s/seppo/commands/seppo_recipe_processor.py\", line 666, in processing\n    raise RuntimeError(\"Error preparing recipe or input data {}\\n{}\".format(args.recipe,args.input))\nRuntimeError: Error preparing recipe or input data ${SEPPO_HOME}/recipies/gamma/recipe_sentinel1_grd.py -t -r\nhttps://datapool.asf.alaska.edu/GRD_HD/SA/S1A_IW_GRDH_1SDV_20180409T232311_20180409T232336_021397_024D6D_DA9A.zip\n"
    },
    "Duration_hms": "0:00:07.275025",
    "Duration_sec": "7.275025",
    "EndTime": "2018-09-11T22:17:18.796093",
    "Job": "seppo_recipe_processor.py -z -o s3://data.earth/sar/sentinel1/rtc/20.0m -r '${SEPPO_HOME}/recipies/gamma/recipe_sentinel1_grd.py -t -r' -i https://datapool.asf.alaska.edu/GRD_HD/SA/S1A_IW_GRDH_1SDV_20180409T232311_20180409T232336_021397_024D6D_DA9A.zip",
    "JobID": "silviaterra-s1pa",
    "StartTime": "2018-09-11T22:17:11.521068",
    "User": "ebduser"
}
-----------------------------------------------------------
{
    "Attributes": {
        "Error": "Authentication selected: Basic realm=\"Please enter your Earthdata Login credentials. If you do not have a Earthdata Login, create one at https://urs.earthdata.nasa.gov//users/new\"\nhttps://datapool.asf.alaska.edu/GRD_HD/SA/S1A_IW_GRDH_1SDV_20180409T232336_20180409T232401_021397_024D6D_14AA.zip:\n2018-09-11 22:17:28 ERROR 404: Not Found.\nTraceback (most recent call last):\n  File \"/mnt/s/seppo/commands/seppo_recipe_processor.py\", line 664, in processing\n    in_files = prepare_working_directory (args,tempdir)\n  File \"/mnt/s/seppo/commands/seppo_recipe_processor.py\", line 414, in prepare_working_directory\n    myfile=get_file(args.input,tempdir)\n  File \"/mnt/s/seppo/commands/seppo_recipe_processor.py\", line 327, in get_file\n    myfile=get_https(d_s,d_t='.')\n  File \"/mnt/s/seppo/commands/seppo_recipe_processor.py\", line 228, in get_https\n    raise RuntimeError('Could not retrieve {}'.format(d_s))\nRuntimeError: Could not retrieve https://datapool.asf.alaska.edu/GRD_HD/SA/S1A_IW_GRDH_1SDV_20180409T232336_20180409T232401_021397_024D6D_14AA.zip\n\nDuring handling of the above exception, another exception occurred:\n\nTraceback (most recent call last):\n  File \"/mnt/s/seppo/commands/seppo_recipe_processor.py\", line 764, in <module>\n    main()\n  File \"/mnt/s/seppo/commands/seppo_recipe_processor.py\", line 760, in main\n    return processing(args)\n  File \"/mnt/s/seppo/commands/seppo_recipe_processor.py\", line 666, in processing\n    raise RuntimeError(\"Error preparing recipe or input data {}\\n{}\".format(args.recipe,args.input))\nRuntimeError: Error preparing recipe or input data ${SEPPO_HOME}/recipies/gamma/recipe_sentinel1_grd.py -t -r\nhttps://datapool.asf.alaska.edu/GRD_HD/SA/S1A_IW_GRDH_1SDV_20180409T232336_20180409T232401_021397_024D6D_14AA.zip\n"
    },
    "Duration_hms": "0:00:07.467951",
    "Duration_sec": "7.467951",
    "EndTime": "2018-09-11T22:17:28.804518",
    "Job": "seppo_recipe_processor.py -z -o s3://data.earth/sar/sentinel1/rtc/20.0m -r '${SEPPO_HOME}/recipies/gamma/recipe_sentinel1_grd.py -t -r' -i https://datapool.asf.alaska.edu/GRD_HD/SA/S1A_IW_GRDH_1SDV_20180409T232336_20180409T232401_021397_024D6D_14AA.zip",
    "JobID": "silviaterra-s1pa",
    "StartTime": "2018-09-11T22:17:21.336567",
    "User": "ebduser"
}
-----------------------------------------------------------
{
    "Attributes": {
        "Error": "Authentication selected: Basic realm=\"Please enter your Earthdata Login credentials. If you do not have a Earthdata Login, create one at https://urs.earthdata.nasa.gov//users/new\"\nhttps://datapool.asf.alaska.edu/GRD_HD/SA/S1A_IW_GRDH_1SDV_20180409T232401_20180409T232426_021397_024D6D_B769.zip:\n2018-09-11 22:17:34 ERROR 404: Not Found.\nTraceback (most recent call last):\n  File \"/mnt/s/seppo/commands/seppo_recipe_processor.py\", line 664, in processing\n    in_files = prepare_working_directory (args,tempdir)\n  File \"/mnt/s/seppo/commands/seppo_recipe_processor.py\", line 414, in prepare_working_directory\n    myfile=get_file(args.input,tempdir)\n  File \"/mnt/s/seppo/commands/seppo_recipe_processor.py\", line 327, in get_file\n    myfile=get_https(d_s,d_t='.')\n  File \"/mnt/s/seppo/commands/seppo_recipe_processor.py\", line 228, in get_https\n    raise RuntimeError('Could not retrieve {}'.format(d_s))\nRuntimeError: Could not retrieve https://datapool.asf.alaska.edu/GRD_HD/SA/S1A_IW_GRDH_1SDV_20180409T232401_20180409T232426_021397_024D6D_B769.zip\n\nDuring handling of the above exception, another exception occurred:\n\nTraceback (most recent call last):\n  File \"/mnt/s/seppo/commands/seppo_recipe_processor.py\", line 764, in <module>\n    main()\n  File \"/mnt/s/seppo/commands/seppo_recipe_processor.py\", line 760, in main\n    return processing(args)\n  File \"/mnt/s/seppo/commands/seppo_recipe_processor.py\", line 666, in processing\n    raise RuntimeError(\"Error preparing recipe or input data {}\\n{}\".format(args.recipe,args.input))\nRuntimeError: Error preparing recipe or input data ${SEPPO_HOME}/recipies/gamma/recipe_sentinel1_grd.py -t -r\nhttps://datapool.asf.alaska.edu/GRD_HD/SA/S1A_IW_GRDH_1SDV_20180409T232401_20180409T232426_021397_024D6D_B769.zip\n"
    },
    "Duration_hms": "0:00:06.020097",
    "Duration_sec": "6.020097",
    "EndTime": "2018-09-11T22:17:34.088059",
    "Job": "seppo_recipe_processor.py -z -o s3://data.earth/sar/sentinel1/rtc/20.0m -r '${SEPPO_HOME}/recipies/gamma/recipe_sentinel1_grd.py -t -r' -i https://datapool.asf.alaska.edu/GRD_HD/SA/S1A_IW_GRDH_1SDV_20180409T232401_20180409T232426_021397_024D6D_B769.zip",
    "JobID": "silviaterra-s1pa",
    "StartTime": "2018-09-11T22:17:28.067962",
    "User": "ebduser"
}
-----------------------------------------------------------
{
    "Attributes": {
        "Error": "Authentication selected: Basic realm=\"Please enter your Earthdata Login credentials. If you do not have a Earthdata Login, create one at https://urs.earthdata.nasa.gov//users/new\"\nhttps://datapool.asf.alaska.edu/GRD_HD/SA/S1A_IW_GRDH_1SDV_20180409T232311_20180409T232336_021397_024D6D_DA9A.zip:\n2018-09-11 22:17:38 ERROR 404: Not Found.\nTraceback (most recent call last):\n  File \"/mnt/s/seppo/commands/seppo_recipe_processor.py\", line 664, in processing\n    in_files = prepare_working_directory (args,tempdir)\n  File \"/mnt/s/seppo/commands/seppo_recipe_processor.py\", line 414, in prepare_working_directory\n    myfile=get_file(args.input,tempdir)\n  File \"/mnt/s/seppo/commands/seppo_recipe_processor.py\", line 327, in get_file\n    myfile=get_https(d_s,d_t='.')\n  File \"/mnt/s/seppo/commands/seppo_recipe_processor.py\", line 228, in get_https\n    raise RuntimeError('Could not retrieve {}'.format(d_s))\nRuntimeError: Could not retrieve https://datapool.asf.alaska.edu/GRD_HD/SA/S1A_IW_GRDH_1SDV_20180409T232311_20180409T232336_021397_024D6D_DA9A.zip\n\nDuring handling of the above exception, another exception occurred:\n\nTraceback (most recent call last):\n  File \"/mnt/s/seppo/commands/seppo_recipe_processor.py\", line 764, in <module>\n    main()\n  File \"/mnt/s/seppo/commands/seppo_recipe_processor.py\", line 760, in main\n    return processing(args)\n  File \"/mnt/s/seppo/commands/seppo_recipe_processor.py\", line 666, in processing\n    raise RuntimeError(\"Error preparing recipe or input data {}\\n{}\".format(args.recipe,args.input))\nRuntimeError: Error preparing recipe or input data ${SEPPO_HOME}/recipies/gamma/recipe_sentinel1_grd.py -t -r\nhttps://datapool.asf.alaska.edu/GRD_HD/SA/S1A_IW_GRDH_1SDV_20180409T232311_20180409T232336_021397_024D6D_DA9A.zip\n"
    },
    "Duration_hms": "0:00:07.001160",
    "Duration_sec": "7.00116",
    "EndTime": "2018-09-11T22:17:38.508658",
    "Job": "seppo_recipe_processor.py -z -o s3://data.earth/sar/sentinel1/rtc/20.0m -r '${SEPPO_HOME}/recipies/gamma/recipe_sentinel1_grd.py -t -r' -i https://datapool.asf.alaska.edu/GRD_HD/SA/S1A_IW_GRDH_1SDV_20180409T232311_20180409T232336_021397_024D6D_DA9A.zip",
    "JobID": "silviaterra-s1pa",
    "StartTime": "2018-09-11T22:17:31.507498",
    "User": "ebduser"
}
-----------------------------------------------------------
{
    "Attributes": {
        "Error": "Authentication selected: Basic realm=\"Please enter your Earthdata Login credentials. If you do not have a Earthdata Login, create one at https://urs.earthdata.nasa.gov//users/new\"\nhttps://datapool.asf.alaska.edu/GRD_HD/SA/S1A_IW_GRDH_1SDV_20180409T232336_20180409T232401_021397_024D6D_14AA.zip:\n2018-09-11 22:17:44 ERROR 404: Not Found.\nTraceback (most recent call last):\n  File \"/mnt/s/seppo/commands/seppo_recipe_processor.py\", line 664, in processing\n    in_files = prepare_working_directory (args,tempdir)\n  File \"/mnt/s/seppo/commands/seppo_recipe_processor.py\", line 414, in prepare_working_directory\n    myfile=get_file(args.input,tempdir)\n  File \"/mnt/s/seppo/commands/seppo_recipe_processor.py\", line 327, in get_file\n    myfile=get_https(d_s,d_t='.')\n  File \"/mnt/s/seppo/commands/seppo_recipe_processor.py\", line 228, in get_https\n    raise RuntimeError('Could not retrieve {}'.format(d_s))\nRuntimeError: Could not retrieve https://datapool.asf.alaska.edu/GRD_HD/SA/S1A_IW_GRDH_1SDV_20180409T232336_20180409T232401_021397_024D6D_14AA.zip\n\nDuring handling of the above exception, another exception occurred:\n\nTraceback (most recent call last):\n  File \"/mnt/s/seppo/commands/seppo_recipe_processor.py\", line 764, in <module>\n    main()\n  File \"/mnt/s/seppo/commands/seppo_recipe_processor.py\", line 760, in main\n    return processing(args)\n  File \"/mnt/s/seppo/commands/seppo_recipe_processor.py\", line 666, in processing\n    raise RuntimeError(\"Error preparing recipe or input data {}\\n{}\".format(args.recipe,args.input))\nRuntimeError: Error preparing recipe or input data ${SEPPO_HOME}/recipies/gamma/recipe_sentinel1_grd.py -t -r\nhttps://datapool.asf.alaska.edu/GRD_HD/SA/S1A_IW_GRDH_1SDV_20180409T232336_20180409T232401_021397_024D6D_14AA.zip\n"
    },
    "Duration_hms": "0:00:06.086959",
    "Duration_sec": "6.086959",
    "EndTime": "2018-09-11T22:17:44.176604",
    "Job": "seppo_recipe_processor.py -z -o s3://data.earth/sar/sentinel1/rtc/20.0m -r '${SEPPO_HOME}/recipies/gamma/recipe_sentinel1_grd.py -t -r' -i https://datapool.asf.alaska.edu/GRD_HD/SA/S1A_IW_GRDH_1SDV_20180409T232336_20180409T232401_021397_024D6D_14AA.zip",
    "JobID": "silviaterra-s1pa",
    "StartTime": "2018-09-11T22:17:38.089645",
    "User": "ebduser"
}
-----------------------------------------------------------
{
    "Attributes": {
        "Error": "Authentication selected: Basic realm=\"Please enter your Earthdata Login credentials. If you do not have a Earthdata Login, create one at https://urs.earthdata.nasa.gov//users/new\"\nhttps://datapool.asf.alaska.edu/GRD_HD/SA/S1A_IW_GRDH_1SDV_20180409T232401_20180409T232426_021397_024D6D_B769.zip:\n2018-09-11 22:17:49 ERROR 404: Not Found.\nTraceback (most recent call last):\n  File \"/mnt/s/seppo/commands/seppo_recipe_processor.py\", line 664, in processing\n    in_files = prepare_working_directory (args,tempdir)\n  File \"/mnt/s/seppo/commands/seppo_recipe_processor.py\", line 414, in prepare_working_directory\n    myfile=get_file(args.input,tempdir)\n  File \"/mnt/s/seppo/commands/seppo_recipe_processor.py\", line 327, in get_file\n    myfile=get_https(d_s,d_t='.')\n  File \"/mnt/s/seppo/commands/seppo_recipe_processor.py\", line 228, in get_https\n    raise RuntimeError('Could not retrieve {}'.format(d_s))\nRuntimeError: Could not retrieve https://datapool.asf.alaska.edu/GRD_HD/SA/S1A_IW_GRDH_1SDV_20180409T232401_20180409T232426_021397_024D6D_B769.zip\n\nDuring handling of the above exception, another exception occurred:\n\nTraceback (most recent call last):\n  File \"/mnt/s/seppo/commands/seppo_recipe_processor.py\", line 764, in <module>\n    main()\n  File \"/mnt/s/seppo/commands/seppo_recipe_processor.py\", line 760, in main\n    return processing(args)\n  File \"/mnt/s/seppo/commands/seppo_recipe_processor.py\", line 666, in processing\n    raise RuntimeError(\"Error preparing recipe or input data {}\\n{}\".format(args.recipe,args.input))\nRuntimeError: Error preparing recipe or input data ${SEPPO_HOME}/recipies/gamma/recipe_sentinel1_grd.py -t -r\nhttps://datapool.asf.alaska.edu/GRD_HD/SA/S1A_IW_GRDH_1SDV_20180409T232401_20180409T232426_021397_024D6D_B769.zip\n"
    },
    "Duration_hms": "0:00:05.814949",
    "Duration_sec": "5.814949",
    "EndTime": "2018-09-11T22:17:49.179538",
    "Job": "seppo_recipe_processor.py -z -o s3://data.earth/sar/sentinel1/rtc/20.0m -r '${SEPPO_HOME}/recipies/gamma/recipe_sentinel1_grd.py -t -r' -i https://datapool.asf.alaska.edu/GRD_HD/SA/S1A_IW_GRDH_1SDV_20180409T232401_20180409T232426_021397_024D6D_B769.zip",
    "JobID": "silviaterra-s1pa",
    "StartTime": "2018-09-11T22:17:43.364589",
    "User": "ebduser"
}
-----------------------------------------------------------
{
    "Attributes": {
        "Error": "Authentication selected: Basic realm=\"Please enter your Earthdata Login credentials. If you do not have a Earthdata Login, create one at https://urs.earthdata.nasa.gov//users/new\"\nhttps://datapool.asf.alaska.edu/GRD_HD/SA/S1A_IW_GRDH_1SDV_20180409T232311_20180409T232336_021397_024D6D_DA9A.zip:\n2018-09-11 22:17:53 ERROR 404: Not Found.\nTraceback (most recent call last):\n  File \"/mnt/s/seppo/commands/seppo_recipe_processor.py\", line 664, in processing\n    in_files = prepare_working_directory (args,tempdir)\n  File \"/mnt/s/seppo/commands/seppo_recipe_processor.py\", line 414, in prepare_working_directory\n    myfile=get_file(args.input,tempdir)\n  File \"/mnt/s/seppo/commands/seppo_recipe_processor.py\", line 327, in get_file\n    myfile=get_https(d_s,d_t='.')\n  File \"/mnt/s/seppo/commands/seppo_recipe_processor.py\", line 228, in get_https\n    raise RuntimeError('Could not retrieve {}'.format(d_s))\nRuntimeError: Could not retrieve https://datapool.asf.alaska.edu/GRD_HD/SA/S1A_IW_GRDH_1SDV_20180409T232311_20180409T232336_021397_024D6D_DA9A.zip\n\nDuring handling of the above exception, another exception occurred:\n\nTraceback (most recent call last):\n  File \"/mnt/s/seppo/commands/seppo_recipe_processor.py\", line 764, in <module>\n    main()\n  File \"/mnt/s/seppo/commands/seppo_recipe_processor.py\", line 760, in main\n    return processing(args)\n  File \"/mnt/s/seppo/commands/seppo_recipe_processor.py\", line 666, in processing\n    raise RuntimeError(\"Error preparing recipe or input data {}\\n{}\".format(args.recipe,args.input))\nRuntimeError: Error preparing recipe or input data ${SEPPO_HOME}/recipies/gamma/recipe_sentinel1_grd.py -t -r\nhttps://datapool.asf.alaska.edu/GRD_HD/SA/S1A_IW_GRDH_1SDV_20180409T232311_20180409T232336_021397_024D6D_DA9A.zip\n"
    },
    "Duration_hms": "0:00:05.689362",
    "Duration_sec": "5.689362",
    "EndTime": "2018-09-11T22:17:53.479860",
    "Job": "seppo_recipe_processor.py -z -o s3://data.earth/sar/sentinel1/rtc/20.0m -r '${SEPPO_HOME}/recipies/gamma/recipe_sentinel1_grd.py -t -r' -i https://datapool.asf.alaska.edu/GRD_HD/SA/S1A_IW_GRDH_1SDV_20180409T232311_20180409T232336_021397_024D6D_DA9A.zip",
    "JobID": "silviaterra-s1pa",
    "StartTime": "2018-09-11T22:17:47.790498",
    "User": "ebduser"
}
-----------------------------------------------------------
{
    "Attributes": {
        "Error": "Authentication selected: Basic realm=\"Please enter your Earthdata Login credentials. If you do not have a Earthdata Login, create one at https://urs.earthdata.nasa.gov//users/new\"\nhttps://datapool.asf.alaska.edu/GRD_HD/SA/S1A_IW_GRDH_1SDV_20180409T232336_20180409T232401_021397_024D6D_14AA.zip:\n2018-09-11 22:17:59 ERROR 404: Not Found.\nTraceback (most recent call last):\n  File \"/mnt/s/seppo/commands/seppo_recipe_processor.py\", line 664, in processing\n    in_files = prepare_working_directory (args,tempdir)\n  File \"/mnt/s/seppo/commands/seppo_recipe_processor.py\", line 414, in prepare_working_directory\n    myfile=get_file(args.input,tempdir)\n  File \"/mnt/s/seppo/commands/seppo_recipe_processor.py\", line 327, in get_file\n    myfile=get_https(d_s,d_t='.')\n  File \"/mnt/s/seppo/commands/seppo_recipe_processor.py\", line 228, in get_https\n    raise RuntimeError('Could not retrieve {}'.format(d_s))\nRuntimeError: Could not retrieve https://datapool.asf.alaska.edu/GRD_HD/SA/S1A_IW_GRDH_1SDV_20180409T232336_20180409T232401_021397_024D6D_14AA.zip\n\nDuring handling of the above exception, another exception occurred:\n\nTraceback (most recent call last):\n  File \"/mnt/s/seppo/commands/seppo_recipe_processor.py\", line 764, in <module>\n    main()\n  File \"/mnt/s/seppo/commands/seppo_recipe_processor.py\", line 760, in main\n    return processing(args)\n  File \"/mnt/s/seppo/commands/seppo_recipe_processor.py\", line 666, in processing\n    raise RuntimeError(\"Error preparing recipe or input data {}\\n{}\".format(args.recipe,args.input))\nRuntimeError: Error preparing recipe or input data ${SEPPO_HOME}/recipies/gamma/recipe_sentinel1_grd.py -t -r\nhttps://datapool.asf.alaska.edu/GRD_HD/SA/S1A_IW_GRDH_1SDV_20180409T232336_20180409T232401_021397_024D6D_14AA.zip\n"
    },
    "Duration_hms": "0:00:05.907785",
    "Duration_sec": "5.907785",
    "EndTime": "2018-09-11T22:17:59.364840",
    "Job": "seppo_recipe_processor.py -z -o s3://data.earth/sar/sentinel1/rtc/20.0m -r '${SEPPO_HOME}/recipies/gamma/recipe_sentinel1_grd.py -t -r' -i https://datapool.asf.alaska.edu/GRD_HD/SA/S1A_IW_GRDH_1SDV_20180409T232336_20180409T232401_021397_024D6D_14AA.zip",
    "JobID": "silviaterra-s1pa",
    "StartTime": "2018-09-11T22:17:53.457055",
    "User": "ebduser"
}
-----------------------------------------------------------
{
    "Attributes": {
        "Error": "Authentication selected: Basic realm=\"Please enter your Earthdata Login credentials. If you do not have a Earthdata Login, create one at https://urs.earthdata.nasa.gov//users/new\"\nhttps://datapool.asf.alaska.edu/GRD_HD/SA/S1A_IW_GRDH_1SDV_20180409T232401_20180409T232426_021397_024D6D_B769.zip:\n2018-09-11 22:18:04 ERROR 404: Not Found.\nTraceback (most recent call last):\n  File \"/mnt/s/seppo/commands/seppo_recipe_processor.py\", line 664, in processing\n    in_files = prepare_working_directory (args,tempdir)\n  File \"/mnt/s/seppo/commands/seppo_recipe_processor.py\", line 414, in prepare_working_directory\n    myfile=get_file(args.input,tempdir)\n  File \"/mnt/s/seppo/commands/seppo_recipe_processor.py\", line 327, in get_file\n    myfile=get_https(d_s,d_t='.')\n  File \"/mnt/s/seppo/commands/seppo_recipe_processor.py\", line 228, in get_https\n    raise RuntimeError('Could not retrieve {}'.format(d_s))\nRuntimeError: Could not retrieve https://datapool.asf.alaska.edu/GRD_HD/SA/S1A_IW_GRDH_1SDV_20180409T232401_20180409T232426_021397_024D6D_B769.zip\n\nDuring handling of the above exception, another exception occurred:\n\nTraceback (most recent call last):\n  File \"/mnt/s/seppo/commands/seppo_recipe_processor.py\", line 764, in <module>\n    main()\n  File \"/mnt/s/seppo/commands/seppo_recipe_processor.py\", line 760, in main\n    return processing(args)\n  File \"/mnt/s/seppo/commands/seppo_recipe_processor.py\", line 666, in processing\n    raise RuntimeError(\"Error preparing recipe or input data {}\\n{}\".format(args.recipe,args.input))\nRuntimeError: Error preparing recipe or input data ${SEPPO_HOME}/recipies/gamma/recipe_sentinel1_grd.py -t -r\nhttps://datapool.asf.alaska.edu/GRD_HD/SA/S1A_IW_GRDH_1SDV_20180409T232401_20180409T232426_021397_024D6D_B769.zip\n"
    },
    "Duration_hms": "0:00:06.347426",
    "Duration_sec": "6.347426",
    "EndTime": "2018-09-11T22:18:04.809123",
    "Job": "seppo_recipe_processor.py -z -o s3://data.earth/sar/sentinel1/rtc/20.0m -r '${SEPPO_HOME}/recipies/gamma/recipe_sentinel1_grd.py -t -r' -i https://datapool.asf.alaska.edu/GRD_HD/SA/S1A_IW_GRDH_1SDV_20180409T232401_20180409T232426_021397_024D6D_B769.zip",
    "JobID": "silviaterra-s1pa",
    "StartTime": "2018-09-11T22:17:58.461697",
    "User": "ebduser"
}
-----------------------------------------------------------
{
    "Attributes": {
        "Error": "Authentication selected: Basic realm=\"Please enter your Earthdata Login credentials. If you do not have a Earthdata Login, create one at https://urs.earthdata.nasa.gov//users/new\"\nhttps://datapool.asf.alaska.edu/GRD_HD/SA/S1A_IW_GRDH_1SDV_20180409T232311_20180409T232336_021397_024D6D_DA9A.zip:\n2018-09-11 22:18:08 ERROR 404: Not Found.\nTraceback (most recent call last):\n  File \"/mnt/s/seppo/commands/seppo_recipe_processor.py\", line 664, in processing\n    in_files = prepare_working_directory (args,tempdir)\n  File \"/mnt/s/seppo/commands/seppo_recipe_processor.py\", line 414, in prepare_working_directory\n    myfile=get_file(args.input,tempdir)\n  File \"/mnt/s/seppo/commands/seppo_recipe_processor.py\", line 327, in get_file\n    myfile=get_https(d_s,d_t='.')\n  File \"/mnt/s/seppo/commands/seppo_recipe_processor.py\", line 228, in get_https\n    raise RuntimeError('Could not retrieve {}'.format(d_s))\nRuntimeError: Could not retrieve https://datapool.asf.alaska.edu/GRD_HD/SA/S1A_IW_GRDH_1SDV_20180409T232311_20180409T232336_021397_024D6D_DA9A.zip\n\nDuring handling of the above exception, another exception occurred:\n\nTraceback (most recent call last):\n  File \"/mnt/s/seppo/commands/seppo_recipe_processor.py\", line 764, in <module>\n    main()\n  File \"/mnt/s/seppo/commands/seppo_recipe_processor.py\", line 760, in main\n    return processing(args)\n  File \"/mnt/s/seppo/commands/seppo_recipe_processor.py\", line 666, in processing\n    raise RuntimeError(\"Error preparing recipe or input data {}\\n{}\".format(args.recipe,args.input))\nRuntimeError: Error preparing recipe or input data ${SEPPO_HOME}/recipies/gamma/recipe_sentinel1_grd.py -t -r\nhttps://datapool.asf.alaska.edu/GRD_HD/SA/S1A_IW_GRDH_1SDV_20180409T232311_20180409T232336_021397_024D6D_DA9A.zip\n"
    },
    "Duration_hms": "0:00:06.204926",
    "Duration_sec": "6.204926",
    "EndTime": "2018-09-11T22:18:08.956752",
    "Job": "seppo_recipe_processor.py -z -o s3://data.earth/sar/sentinel1/rtc/20.0m -r '${SEPPO_HOME}/recipies/gamma/recipe_sentinel1_grd.py -t -r' -i https://datapool.asf.alaska.edu/GRD_HD/SA/S1A_IW_GRDH_1SDV_20180409T232311_20180409T232336_021397_024D6D_DA9A.zip",
    "JobID": "silviaterra-s1pa",
    "StartTime": "2018-09-11T22:18:02.751826",
    "User": "ebduser"
}
-----------------------------------------------------------
{
    "Attributes": {
        "Error": "Authentication selected: Basic realm=\"Please enter your Earthdata Login credentials. If you do not have a Earthdata Login, create one at https://urs.earthdata.nasa.gov//users/new\"\nhttps://datapool.asf.alaska.edu/GRD_HD/SA/S1A_IW_GRDH_1SDV_20180409T232336_20180409T232401_021397_024D6D_14AA.zip:\n2018-09-11 22:18:15 ERROR 404: Not Found.\nTraceback (most recent call last):\n  File \"/mnt/s/seppo/commands/seppo_recipe_processor.py\", line 664, in processing\n    in_files = prepare_working_directory (args,tempdir)\n  File \"/mnt/s/seppo/commands/seppo_recipe_processor.py\", line 414, in prepare_working_directory\n    myfile=get_file(args.input,tempdir)\n  File \"/mnt/s/seppo/commands/seppo_recipe_processor.py\", line 327, in get_file\n    myfile=get_https(d_s,d_t='.')\n  File \"/mnt/s/seppo/commands/seppo_recipe_processor.py\", line 228, in get_https\n    raise RuntimeError('Could not retrieve {}'.format(d_s))\nRuntimeError: Could not retrieve https://datapool.asf.alaska.edu/GRD_HD/SA/S1A_IW_GRDH_1SDV_20180409T232336_20180409T232401_021397_024D6D_14AA.zip\n\nDuring handling of the above exception, another exception occurred:\n\nTraceback (most recent call last):\n  File \"/mnt/s/seppo/commands/seppo_recipe_processor.py\", line 764, in <module>\n    main()\n  File \"/mnt/s/seppo/commands/seppo_recipe_processor.py\", line 760, in main\n    return processing(args)\n  File \"/mnt/s/seppo/commands/seppo_recipe_processor.py\", line 666, in processing\n    raise RuntimeError(\"Error preparing recipe or input data {}\\n{}\".format(args.recipe,args.input))\nRuntimeError: Error preparing recipe or input data ${SEPPO_HOME}/recipies/gamma/recipe_sentinel1_grd.py -t -r\nhttps://datapool.asf.alaska.edu/GRD_HD/SA/S1A_IW_GRDH_1SDV_20180409T232336_20180409T232401_021397_024D6D_14AA.zip\n"
    },
    "Duration_hms": "0:00:06.436801",
    "Duration_sec": "6.436801",
    "EndTime": "2018-09-11T22:18:15.072009",
    "Job": "seppo_recipe_processor.py -z -o s3://data.earth/sar/sentinel1/rtc/20.0m -r '${SEPPO_HOME}/recipies/gamma/recipe_sentinel1_grd.py -t -r' -i https://datapool.asf.alaska.edu/GRD_HD/SA/S1A_IW_GRDH_1SDV_20180409T232336_20180409T232401_021397_024D6D_14AA.zip",
    "JobID": "silviaterra-s1pa",
    "StartTime": "2018-09-11T22:18:08.635208",
    "User": "ebduser"
}
-----------------------------------------------------------
seppo_recipe_processor.py -z -o s3://data.earth/sar/sentinel1/rtc/20.0m -r '${SEPPO_HOME}/recipies/gamma/recipe_sentinel1_grd.py -t -r' -i https://datapool.asf.alaska.edu/GRD_HD/SA/S1A_IW_GRDH_1SDV_20180409T232311_20180409T232336_021397_024D6D_DA9A.zip
-----------------------------------------------------------
seppo_recipe_processor.py -z -o s3://data.earth/sar/sentinel1/rtc/20.0m -r '${SEPPO_HOME}/recipies/gamma/recipe_sentinel1_grd.py -t -r' -i https://datapool.asf.alaska.edu/GRD_HD/SA/S1A_IW_GRDH_1SDV_20180409T232336_20180409T232401_021397_024D6D_14AA.zip
-----------------------------------------------------------
{
    "Attributes": {
        "Error": "Authentication selected: Basic realm=\"Please enter your Earthdata Login credentials. If you do not have a Earthdata Login, create one at https://urs.earthdata.nasa.gov//users/new\"\nhttps://datapool.asf.alaska.edu/GRD_HD/SA/S1A_IW_GRDH_1SDV_20180409T232401_20180409T232426_021397_024D6D_B769.zip:\n2018-09-11 22:18:20 ERROR 404: Not Found.\nTraceback (most recent call last):\n  File \"/mnt/s/seppo/commands/seppo_recipe_processor.py\", line 664, in processing\n    in_files = prepare_working_directory (args,tempdir)\n  File \"/mnt/s/seppo/commands/seppo_recipe_processor.py\", line 414, in prepare_working_directory\n    myfile=get_file(args.input,tempdir)\n  File \"/mnt/s/seppo/commands/seppo_recipe_processor.py\", line 327, in get_file\n    myfile=get_https(d_s,d_t='.')\n  File \"/mnt/s/seppo/commands/seppo_recipe_processor.py\", line 228, in get_https\n    raise RuntimeError('Could not retrieve {}'.format(d_s))\nRuntimeError: Could not retrieve https://datapool.asf.alaska.edu/GRD_HD/SA/S1A_IW_GRDH_1SDV_20180409T232401_20180409T232426_021397_024D6D_B769.zip\n\nDuring handling of the above exception, another exception occurred:\n\nTraceback (most recent call last):\n  File \"/mnt/s/seppo/commands/seppo_recipe_processor.py\", line 764, in <module>\n    main()\n  File \"/mnt/s/seppo/commands/seppo_recipe_processor.py\", line 760, in main\n    return processing(args)\n  File \"/mnt/s/seppo/commands/seppo_recipe_processor.py\", line 666, in processing\n    raise RuntimeError(\"Error preparing recipe or input data {}\\n{}\".format(args.recipe,args.input))\nRuntimeError: Error preparing recipe or input data ${SEPPO_HOME}/recipies/gamma/recipe_sentinel1_grd.py -t -r\nhttps://datapool.asf.alaska.edu/GRD_HD/SA/S1A_IW_GRDH_1SDV_20180409T232401_20180409T232426_021397_024D6D_B769.zip\n"
    },
    "Duration_hms": "0:00:06.739144",
    "Duration_sec": "6.739144",
    "EndTime": "2018-09-11T22:18:20.846217",
    "Job": "seppo_recipe_processor.py -z -o s3://data.earth/sar/sentinel1/rtc/20.0m -r '${SEPPO_HOME}/recipies/gamma/recipe_sentinel1_grd.py -t -r' -i https://datapool.asf.alaska.edu/GRD_HD/SA/S1A_IW_GRDH_1SDV_20180409T232401_20180409T232426_021397_024D6D_B769.zip",
    "JobID": "silviaterra-s1pa",
    "StartTime": "2018-09-11T22:18:14.107073",
    "User": "ebduser"
}
-----------------------------------------------------------
seppo_recipe_processor.py -z -o s3://data.earth/sar/sentinel1/rtc/20.0m -r '${SEPPO_HOME}/recipies/gamma/recipe_sentinel1_grd.py -t -r' -i https://datapool.asf.alaska.edu/GRD_HD/SA/S1A_IW_GRDH_1SDV_20180409T232401_20180409T232426_021397_024D6D_B769.zip
-----------------------------------------------------------
