{
    "Attributes": {
        "Error": "Authentication selected: Basic realm=\"Please enter your Earthdata Login credentials. If you do not have a Earthdata Login, create one at https://urs.earthdata.nasa.gov//users/new\"\nhttps://datapool.asf.alaska.edu/GRD_HD/SA/S1A_IW_GRDH_1SDV_20160128T120552_20160128T120617_009694_00E257_7FA4.zip:\n2018-08-16 22:23:18 ERROR 404: Not Found.\nTraceback (most recent call last):\n  File \"/mnt/s/seppo/commands/seppo_recipe_processor.py\", line 664, in processing\n    in_files = prepare_working_directory (args,tempdir)\n  File \"/mnt/s/seppo/commands/seppo_recipe_processor.py\", line 414, in prepare_working_directory\n    myfile=get_file(args.input,tempdir)\n  File \"/mnt/s/seppo/commands/seppo_recipe_processor.py\", line 327, in get_file\n    myfile=get_https(d_s,d_t='.')\n  File \"/mnt/s/seppo/commands/seppo_recipe_processor.py\", line 228, in get_https\n    raise RuntimeError('Could not retrieve {}'.format(d_s))\nRuntimeError: Could not retrieve https://datapool.asf.alaska.edu/GRD_HD/SA/S1A_IW_GRDH_1SDV_20160128T120552_20160128T120617_009694_00E257_7FA4.zip\n\nDuring handling of the above exception, another exception occurred:\n\nTraceback (most recent call last):\n  File \"/mnt/s/seppo/commands/seppo_recipe_processor.py\", line 764, in <module>\n    main()\n  File \"/mnt/s/seppo/commands/seppo_recipe_processor.py\", line 760, in main\n    return processing(args)\n  File \"/mnt/s/seppo/commands/seppo_recipe_processor.py\", line 666, in processing\n    raise RuntimeError(\"Error preparing recipe or input data {}\\n{}\".format(args.recipe,args.input))\nRuntimeError: Error preparing recipe or input data ${SEPPO_HOME}/recipies/gamma/recipe_sentinel1_grd.py -t -r\nhttps://datapool.asf.alaska.edu/GRD_HD/SA/S1A_IW_GRDH_1SDV_20160128T120552_20160128T120617_009694_00E257_7FA4.zip\n"
    },
    "Duration_hms": "0:00:09.185053",
    "Duration_sec": "9.185053",
    "EndTime": "2018-08-16T22:23:18.273120",
    "Job": "seppo_recipe_processor.py -z -o s3://data.earth/sar/sentinel1/rtc/20.0m -r '${SEPPO_HOME}/recipies/gamma/recipe_sentinel1_grd.py -t -r' -i https://datapool.asf.alaska.edu/GRD_HD/SA/S1A_IW_GRDH_1SDV_20160128T120552_20160128T120617_009694_00E257_7FA4.zip",
    "JobID": "sentinel1-scenes",
    "StartTime": "2018-08-16T22:23:09.088067",
    "User": "ebduser"
}
-----------------------------------------------------------
{
    "Attributes": {
        "Error": "Authentication selected: Basic realm=\"Please enter your Earthdata Login credentials. If you do not have a Earthdata Login, create one at https://urs.earthdata.nasa.gov//users/new\"\n2018-08-16 22:23:51 URL:https://gsfc-ngap-p-203cc084-8993-5a7c-a43d-5afbd8469852.s3.amazonaws.com/S1A_IW_GRDH_1SDV_20170726T001027_20170726T001052_017635_01D845_42FE.zip?AWSAccessKeyId=AKIAJ2F6ERO2DFXZ7PUQ&Signature=RhPBnh%2F0yNgdY0cE%2BfJejkmRuGQ%3D&Expires=1534501415&userid=josefk [1042739753/1042739753] -> \"./S1A_IW_GRDH_1SDV_20170726T001027_20170726T001052_017635_01D845_42FE.zip\" [1]\n/mnt/s/GAMMA/GAMMA_Current/ISP/bin/par_S1_GRD: /mnt/s/anaconda/envs/seppo/lib/libtiff.so.5: no version information available (required by /usr/lib/x86_64-linux-gnu/libpoppler.so.58)\n/mnt/s/GAMMA/GAMMA_Current/ISP/bin/par_S1_GRD: symbol lookup error: /usr/lib/libgdal.so.1: undefined symbol: sqlite3_column_table_name\nTraceback (most recent call last):\n  File \"/mnt/s/seppo/commands/seppo_gamma_proc.py\", line 173, in <module>\n    main(sys.argv)\n  File \"/mnt/s/seppo/commands/seppo_gamma_proc.py\", line 170, in main\n    GT.gamma_proc(args)\n  File \"/mnt/s/seppo/programs/lib/seppopy/tools/GammaTools.py\", line 574, in gamma_proc\n    _sp.check_call(cmd.split())\n  File \"/mnt/s/anaconda/envs/seppo/lib/python3.6/subprocess.py\", line 291, in check_call\n    raise CalledProcessError(retcode, cmd)\nsubprocess.CalledProcessError: Command '['/mnt/s/GAMMA/GAMMA_Current/ISP/bin/par_S1_GRD', './S1A_IW_GRDH_1SDV_20170726T001027_20170726T001052_017635_01D845_42FE.SAFE/measurement/s1a-iw-grd-vv-20170726t001027-20170726t001052-017635-01d845-001.tiff', './S1A_IW_GRDH_1SDV_20170726T001027_20170726T001052_017635_01D845_42FE.SAFE/annotation/s1a-iw-grd-vv-20170726t001027-20170726t001052-017635-01d845-001.xml', './S1A_IW_GRDH_1SDV_20170726T001027_20170726T001052_017635_01D845_42FE.SAFE/annotation/calibration/calibration-s1a-iw-grd-vv-20170726t001027-20170726t001052-017635-01d845-001.xml', './S1A_IW_GRDH_1SDV_20170726T001027_20170726T001052_017635_01D845_42FE.SAFE/annotation/calibration/noise-s1a-iw-grd-vv-20170726t001027-20170726t001052-017635-01d845-001.xml', './temp_im.par', './temp_im', '-', '-', '1', '-', './temp_noise_im']' returned non-zero exit status 127.\n/mnt/s/GAMMA/GAMMA_Current/ISP/bin/par_S1_GRD: /mnt/s/anaconda/envs/seppo/lib/libtiff.so.5: no version information available (required by /usr/lib/x86_64-linux-gnu/libpoppler.so.58)\n/mnt/s/GAMMA/GAMMA_Current/ISP/bin/par_S1_GRD: symbol lookup error: /usr/lib/libgdal.so.1: undefined symbol: sqlite3_column_table_name\nTraceback (most recent call last):\n  File \"/mnt/s/seppo/commands/seppo_gamma_proc.py\", line 173, in <module>\n    main(sys.argv)\n  File \"/mnt/s/seppo/commands/seppo_gamma_proc.py\", line 170, in main\n    GT.gamma_proc(args)\n  File \"/mnt/s/seppo/programs/lib/seppopy/tools/GammaTools.py\", line 574, in gamma_proc\n    _sp.check_call(cmd.split())\n  File \"/mnt/s/anaconda/envs/seppo/lib/python3.6/subprocess.py\", line 291, in check_call\n    raise CalledProcessError(retcode, cmd)\nsubprocess.CalledProcessError: Command '['/mnt/s/GAMMA/GAMMA_Current/ISP/bin/par_S1_GRD', './S1A_IW_GRDH_1SDV_20170726T001027_20170726T001052_017635_01D845_42FE.SAFE/measurement/s1a-iw-grd-vh-20170726t001027-20170726t001052-017635-01d845-002.tiff', './S1A_IW_GRDH_1SDV_20170726T001027_20170726T001052_017635_01D845_42FE.SAFE/annotation/s1a-iw-grd-vh-20170726t001027-20170726t001052-017635-01d845-002.xml', './S1A_IW_GRDH_1SDV_20170726T001027_20170726T001052_017635_01D845_42FE.SAFE/annotation/calibration/calibration-s1a-iw-grd-vh-20170726t001027-20170726t001052-017635-01d845-002.xml', './S1A_IW_GRDH_1SDV_20170726T001027_20170726T001052_017635_01D845_42FE.SAFE/annotation/calibration/noise-s1a-iw-grd-vh-20170726t001027-20170726t001052-017635-01d845-002.xml', './temp_im.par', './temp_im', '-', '-', '1', '-', './temp_noise_im']' returned non-zero exit status 127.\nTraceback (most recent call last):\n  File \"/dev/shm/seppoRPme07bmav/recipe_sentinel1_grd.py\", line 228, in <module>\n    cmd='seppo_DNDIFF.py {} {} {} 100'.format(imgsbrowse[0],imgsbrowse[1],'temp_browse_ratio.tif')\nIndexError: list index out of range\nsh: 0: getcwd() failed: No such file or directory\n/mnt/s/seppo/commands/seppo_recipe_processor.py:563: UserWarning: Not a valid source: 20.0m.zip\n  warnings.warn(\"Not a valid source: {}\".format(src))\nTraceback (most recent call last):\n  File \"/mnt/s/seppo/commands/seppo_recipe_processor.py\", line 696, in processing\n    shutil.rmtree(tempdir)\n  File \"/mnt/s/anaconda/envs/seppo/lib/python3.6/shutil.py\", line 471, in rmtree\n    onerror(os.lstat, path, sys.exc_info())\n  File \"/mnt/s/anaconda/envs/seppo/lib/python3.6/shutil.py\", line 469, in rmtree\n    orig_st = os.lstat(path)\nFileNotFoundError: [Errno 2] No such file or directory: '/dev/shm/seppoRPme07bmav'\n\nDuring handling of the above exception, another exception occurred:\n\nTraceback (most recent call last):\n  File \"/mnt/s/seppo/commands/seppo_recipe_processor.py\", line 764, in <module>\n    main()\n  File \"/mnt/s/seppo/commands/seppo_recipe_processor.py\", line 760, in main\n    return processing(args)\n  File \"/mnt/s/seppo/commands/seppo_recipe_processor.py\", line 698, in processing\n    raise RuntimeError('Error deleting tempdir. Why???')\nRuntimeError: Error deleting tempdir. Why???\n"
    },
    "Duration_hms": "0:02:42.256559",
    "Duration_sec": "162.256559",
    "EndTime": "2018-08-16T22:26:09.871372",
    "Job": "seppo_recipe_processor.py -z -o s3://data.earth/sar/sentinel1/rtc/20.0m -r '${SEPPO_HOME}/recipies/gamma/recipe_sentinel1_grd.py -t -r' -i https://datapool.asf.alaska.edu/GRD_HD/SA/S1A_IW_GRDH_1SDV_20170726T001027_20170726T001052_017635_01D845_42FE.zip",
    "JobID": "sentinel1-scenes",
    "StartTime": "2018-08-16T22:23:27.614813",
    "User": "ebduser"
}
-----------------------------------------------------------
{
    "Attributes": {
        "Error": "Authentication selected: Basic realm=\"Please enter your Earthdata Login credentials. If you do not have a Earthdata Login, create one at https://urs.earthdata.nasa.gov//users/new\"\n2018-08-16 22:32:22 URL:https://gsfc-ngap-p-203cc084-8993-5a7c-a43d-5afbd8469852.s3.amazonaws.com/S1A_IW_GRDH_1SDV_20170103T001022_20170103T001047_014660_017D8A_536C.zip?Signature=%2FBj2A7Jk1dC3J73wBL6OYJDAkdw%3D&AWSAccessKeyId=AKIAJ2F6ERO2DFXZ7PUQ&Expires=1534501922&userid=josefk [1053242673/1053242673] -> \"./S1A_IW_GRDH_1SDV_20170103T001022_20170103T001047_014660_017D8A_536C.zip\" [1]\n/mnt/s/GAMMA/GAMMA_Current/ISP/bin/par_S1_GRD: /mnt/s/anaconda/envs/seppo/lib/libtiff.so.5: no version information available (required by /usr/lib/x86_64-linux-gnu/libpoppler.so.58)\n/mnt/s/GAMMA/GAMMA_Current/ISP/bin/par_S1_GRD: symbol lookup error: /usr/lib/libgdal.so.1: undefined symbol: sqlite3_column_table_name\nTraceback (most recent call last):\n  File \"/mnt/s/seppo/commands/seppo_gamma_proc.py\", line 173, in <module>\n    main(sys.argv)\n  File \"/mnt/s/seppo/commands/seppo_gamma_proc.py\", line 170, in main\n    GT.gamma_proc(args)\n  File \"/mnt/s/seppo/programs/lib/seppopy/tools/GammaTools.py\", line 574, in gamma_proc\n    _sp.check_call(cmd.split())\n  File \"/mnt/s/anaconda/envs/seppo/lib/python3.6/subprocess.py\", line 291, in check_call\n    raise CalledProcessError(retcode, cmd)\nsubprocess.CalledProcessError: Command '['/mnt/s/GAMMA/GAMMA_Current/ISP/bin/par_S1_GRD', './S1A_IW_GRDH_1SDV_20170103T001022_20170103T001047_014660_017D8A_536C.SAFE/measurement/s1a-iw-grd-vv-20170103t001022-20170103t001047-014660-017d8a-001.tiff', './S1A_IW_GRDH_1SDV_20170103T001022_20170103T001047_014660_017D8A_536C.SAFE/annotation/s1a-iw-grd-vv-20170103t001022-20170103t001047-014660-017d8a-001.xml', './S1A_IW_GRDH_1SDV_20170103T001022_20170103T001047_014660_017D8A_536C.SAFE/annotation/calibration/calibration-s1a-iw-grd-vv-20170103t001022-20170103t001047-014660-017d8a-001.xml', './S1A_IW_GRDH_1SDV_20170103T001022_20170103T001047_014660_017D8A_536C.SAFE/annotation/calibration/noise-s1a-iw-grd-vv-20170103t001022-20170103t001047-014660-017d8a-001.xml', './temp_im.par', './temp_im', '-', '-', '1', '-', './temp_noise_im']' returned non-zero exit status 127.\n/mnt/s/GAMMA/GAMMA_Current/ISP/bin/par_S1_GRD: /mnt/s/anaconda/envs/seppo/lib/libtiff.so.5: no version information available (required by /usr/lib/x86_64-linux-gnu/libpoppler.so.58)\n/mnt/s/GAMMA/GAMMA_Current/ISP/bin/par_S1_GRD: symbol lookup error: /usr/lib/libgdal.so.1: undefined symbol: sqlite3_column_table_name\nTraceback (most recent call last):\n  File \"/mnt/s/seppo/commands/seppo_gamma_proc.py\", line 173, in <module>\n    main(sys.argv)\n  File \"/mnt/s/seppo/commands/seppo_gamma_proc.py\", line 170, in main\n    GT.gamma_proc(args)\n  File \"/mnt/s/seppo/programs/lib/seppopy/tools/GammaTools.py\", line 574, in gamma_proc\n    _sp.check_call(cmd.split())\n  File \"/mnt/s/anaconda/envs/seppo/lib/python3.6/subprocess.py\", line 291, in check_call\n    raise CalledProcessError(retcode, cmd)\nsubprocess.CalledProcessError: Command '['/mnt/s/GAMMA/GAMMA_Current/ISP/bin/par_S1_GRD', './S1A_IW_GRDH_1SDV_20170103T001022_20170103T001047_014660_017D8A_536C.SAFE/measurement/s1a-iw-grd-vh-20170103t001022-20170103t001047-014660-017d8a-002.tiff', './S1A_IW_GRDH_1SDV_20170103T001022_20170103T001047_014660_017D8A_536C.SAFE/annotation/s1a-iw-grd-vh-20170103t001022-20170103t001047-014660-017d8a-002.xml', './S1A_IW_GRDH_1SDV_20170103T001022_20170103T001047_014660_017D8A_536C.SAFE/annotation/calibration/calibration-s1a-iw-grd-vh-20170103t001022-20170103t001047-014660-017d8a-002.xml', './S1A_IW_GRDH_1SDV_20170103T001022_20170103T001047_014660_017D8A_536C.SAFE/annotation/calibration/noise-s1a-iw-grd-vh-20170103t001022-20170103t001047-014660-017d8a-002.xml', './temp_im.par', './temp_im', '-', '-', '1', '-', './temp_noise_im']' returned non-zero exit status 127.\nTraceback (most recent call last):\n  File \"/dev/shm/seppoRPovfj541c/recipe_sentinel1_grd.py\", line 228, in <module>\n    cmd='seppo_DNDIFF.py {} {} {} 100'.format(imgsbrowse[0],imgsbrowse[1],'temp_browse_ratio.tif')\nIndexError: list index out of range\nsh: 0: getcwd() failed: No such file or directory\n/mnt/s/seppo/commands/seppo_recipe_processor.py:563: UserWarning: Not a valid source: 20.0m.zip\n  warnings.warn(\"Not a valid source: {}\".format(src))\nTraceback (most recent call last):\n  File \"/mnt/s/seppo/commands/seppo_recipe_processor.py\", line 696, in processing\n    shutil.rmtree(tempdir)\n  File \"/mnt/s/anaconda/envs/seppo/lib/python3.6/shutil.py\", line 471, in rmtree\n    onerror(os.lstat, path, sys.exc_info())\n  File \"/mnt/s/anaconda/envs/seppo/lib/python3.6/shutil.py\", line 469, in rmtree\n    orig_st = os.lstat(path)\nFileNotFoundError: [Errno 2] No such file or directory: '/dev/shm/seppoRPovfj541c'\n\nDuring handling of the above exception, another exception occurred:\n\nTraceback (most recent call last):\n  File \"/mnt/s/seppo/commands/seppo_recipe_processor.py\", line 764, in <module>\n    main()\n  File \"/mnt/s/seppo/commands/seppo_recipe_processor.py\", line 760, in main\n    return processing(args)\n  File \"/mnt/s/seppo/commands/seppo_recipe_processor.py\", line 698, in processing\n    raise RuntimeError('Error deleting tempdir. Why???')\nRuntimeError: Error deleting tempdir. Why???\n"
    },
    "Duration_hms": "0:02:45.390795",
    "Duration_sec": "165.390795",
    "EndTime": "2018-08-16T22:34:39.078757",
    "Job": "seppo_recipe_processor.py -z -o s3://data.earth/sar/sentinel1/rtc/20.0m -r '${SEPPO_HOME}/recipies/gamma/recipe_sentinel1_grd.py -t -r' -i https://datapool.asf.alaska.edu/GRD_HD/SA/S1A_IW_GRDH_1SDV_20170103T001022_20170103T001047_014660_017D8A_536C.zip",
    "JobID": "sentinel1-scenes",
    "StartTime": "2018-08-16T22:31:53.687962",
    "User": "ebduser"
}
-----------------------------------------------------------
{
    "Attributes": {
        "Error": "Authentication selected: Basic realm=\"Please enter your Earthdata Login credentials. If you do not have a Earthdata Login, create one at https://urs.earthdata.nasa.gov//users/new\"\nhttps://datapool.asf.alaska.edu/GRD_HD/SA/S1A_IW_GRDH_1SDV_20160128T120552_20160128T120617_009694_00E257_7FA4.zip:\n2018-08-16 22:34:57 ERROR 404: Not Found.\nTraceback (most recent call last):\n  File \"/mnt/s/seppo/commands/seppo_recipe_processor.py\", line 664, in processing\n    in_files = prepare_working_directory (args,tempdir)\n  File \"/mnt/s/seppo/commands/seppo_recipe_processor.py\", line 414, in prepare_working_directory\n    myfile=get_file(args.input,tempdir)\n  File \"/mnt/s/seppo/commands/seppo_recipe_processor.py\", line 327, in get_file\n    myfile=get_https(d_s,d_t='.')\n  File \"/mnt/s/seppo/commands/seppo_recipe_processor.py\", line 228, in get_https\n    raise RuntimeError('Could not retrieve {}'.format(d_s))\nRuntimeError: Could not retrieve https://datapool.asf.alaska.edu/GRD_HD/SA/S1A_IW_GRDH_1SDV_20160128T120552_20160128T120617_009694_00E257_7FA4.zip\n\nDuring handling of the above exception, another exception occurred:\n\nTraceback (most recent call last):\n  File \"/mnt/s/seppo/commands/seppo_recipe_processor.py\", line 764, in <module>\n    main()\n  File \"/mnt/s/seppo/commands/seppo_recipe_processor.py\", line 760, in main\n    return processing(args)\n  File \"/mnt/s/seppo/commands/seppo_recipe_processor.py\", line 666, in processing\n    raise RuntimeError(\"Error preparing recipe or input data {}\\n{}\".format(args.recipe,args.input))\nRuntimeError: Error preparing recipe or input data ${SEPPO_HOME}/recipies/gamma/recipe_sentinel1_grd.py -t -r\nhttps://datapool.asf.alaska.edu/GRD_HD/SA/S1A_IW_GRDH_1SDV_20160128T120552_20160128T120617_009694_00E257_7FA4.zip\n"
    },
    "Duration_hms": "0:00:08.990919",
    "Duration_sec": "8.990919",
    "EndTime": "2018-08-16T22:34:57.601844",
    "Job": "seppo_recipe_processor.py -z -o s3://data.earth/sar/sentinel1/rtc/20.0m -r '${SEPPO_HOME}/recipies/gamma/recipe_sentinel1_grd.py -t -r' -i https://datapool.asf.alaska.edu/GRD_HD/SA/S1A_IW_GRDH_1SDV_20160128T120552_20160128T120617_009694_00E257_7FA4.zip",
    "JobID": "sentinel1-scenes",
    "StartTime": "2018-08-16T22:34:48.610925",
    "User": "ebduser"
}
-----------------------------------------------------------
{
    "Attributes": {
        "Error": "Authentication selected: Basic realm=\"Please enter your Earthdata Login credentials. If you do not have a Earthdata Login, create one at https://urs.earthdata.nasa.gov//users/new\"\nhttps://datapool.asf.alaska.edu/GRD_HD/SA/S1A_IW_GRDH_1SDV_20160128T120552_20160128T120617_009694_00E257_7FA4.zip:\n2018-08-16 22:40:09 ERROR 404: Not Found.\nTraceback (most recent call last):\n  File \"/mnt/s/seppo/commands/seppo_recipe_processor.py\", line 664, in processing\n    in_files = prepare_working_directory (args,tempdir)\n  File \"/mnt/s/seppo/commands/seppo_recipe_processor.py\", line 414, in prepare_working_directory\n    myfile=get_file(args.input,tempdir)\n  File \"/mnt/s/seppo/commands/seppo_recipe_processor.py\", line 327, in get_file\n    myfile=get_https(d_s,d_t='.')\n  File \"/mnt/s/seppo/commands/seppo_recipe_processor.py\", line 228, in get_https\n    raise RuntimeError('Could not retrieve {}'.format(d_s))\nRuntimeError: Could not retrieve https://datapool.asf.alaska.edu/GRD_HD/SA/S1A_IW_GRDH_1SDV_20160128T120552_20160128T120617_009694_00E257_7FA4.zip\n\nDuring handling of the above exception, another exception occurred:\n\nTraceback (most recent call last):\n  File \"/mnt/s/seppo/commands/seppo_recipe_processor.py\", line 764, in <module>\n    main()\n  File \"/mnt/s/seppo/commands/seppo_recipe_processor.py\", line 760, in main\n    return processing(args)\n  File \"/mnt/s/seppo/commands/seppo_recipe_processor.py\", line 666, in processing\n    raise RuntimeError(\"Error preparing recipe or input data {}\\n{}\".format(args.recipe,args.input))\nRuntimeError: Error preparing recipe or input data ${SEPPO_HOME}/recipies/gamma/recipe_sentinel1_grd.py -t -r\nhttps://datapool.asf.alaska.edu/GRD_HD/SA/S1A_IW_GRDH_1SDV_20160128T120552_20160128T120617_009694_00E257_7FA4.zip\n"
    },
    "Duration_hms": "0:00:08.869807",
    "Duration_sec": "8.869807",
    "EndTime": "2018-08-16T22:40:09.591872",
    "Job": "seppo_recipe_processor.py -z -o s3://data.earth/sar/sentinel1/rtc/20.0m -r '${SEPPO_HOME}/recipies/gamma/recipe_sentinel1_grd.py -t -r' -i https://datapool.asf.alaska.edu/GRD_HD/SA/S1A_IW_GRDH_1SDV_20160128T120552_20160128T120617_009694_00E257_7FA4.zip",
    "JobID": "sentinel1-scenes",
    "StartTime": "2018-08-16T22:40:00.722065",
    "User": "ebduser"
}
-----------------------------------------------------------
{
    "Attributes": {
        "Error": "Authentication selected: Basic realm=\"Please enter your Earthdata Login credentials. If you do not have a Earthdata Login, create one at https://urs.earthdata.nasa.gov//users/new\"\nhttps://datapool.asf.alaska.edu/GRD_HD/SA/S1A_IW_GRDH_1SDV_20160128T120552_20160128T120617_009694_00E257_7FA4.zip:\n2018-08-16 22:40:25 ERROR 404: Not Found.\nTraceback (most recent call last):\n  File \"/mnt/s/seppo/commands/seppo_recipe_processor.py\", line 664, in processing\n    in_files = prepare_working_directory (args,tempdir)\n  File \"/mnt/s/seppo/commands/seppo_recipe_processor.py\", line 414, in prepare_working_directory\n    myfile=get_file(args.input,tempdir)\n  File \"/mnt/s/seppo/commands/seppo_recipe_processor.py\", line 327, in get_file\n    myfile=get_https(d_s,d_t='.')\n  File \"/mnt/s/seppo/commands/seppo_recipe_processor.py\", line 228, in get_https\n    raise RuntimeError('Could not retrieve {}'.format(d_s))\nRuntimeError: Could not retrieve https://datapool.asf.alaska.edu/GRD_HD/SA/S1A_IW_GRDH_1SDV_20160128T120552_20160128T120617_009694_00E257_7FA4.zip\n\nDuring handling of the above exception, another exception occurred:\n\nTraceback (most recent call last):\n  File \"/mnt/s/seppo/commands/seppo_recipe_processor.py\", line 764, in <module>\n    main()\n  File \"/mnt/s/seppo/commands/seppo_recipe_processor.py\", line 760, in main\n    return processing(args)\n  File \"/mnt/s/seppo/commands/seppo_recipe_processor.py\", line 666, in processing\n    raise RuntimeError(\"Error preparing recipe or input data {}\\n{}\".format(args.recipe,args.input))\nRuntimeError: Error preparing recipe or input data ${SEPPO_HOME}/recipies/gamma/recipe_sentinel1_grd.py -t -r\nhttps://datapool.asf.alaska.edu/GRD_HD/SA/S1A_IW_GRDH_1SDV_20160128T120552_20160128T120617_009694_00E257_7FA4.zip\n"
    },
    "Duration_hms": "0:00:06.573638",
    "Duration_sec": "6.573638",
    "EndTime": "2018-08-16T22:40:25.423715",
    "Job": "seppo_recipe_processor.py -z -o s3://data.earth/sar/sentinel1/rtc/20.0m -r '${SEPPO_HOME}/recipies/gamma/recipe_sentinel1_grd.py -t -r' -i https://datapool.asf.alaska.edu/GRD_HD/SA/S1A_IW_GRDH_1SDV_20160128T120552_20160128T120617_009694_00E257_7FA4.zip",
    "JobID": "sentinel1-scenes",
    "StartTime": "2018-08-16T22:40:18.850077",
    "User": "ebduser"
}
-----------------------------------------------------------
{
    "Attributes": {
        "Error": "Authentication selected: Basic realm=\"Please enter your Earthdata Login credentials. If you do not have a Earthdata Login, create one at https://urs.earthdata.nasa.gov//users/new\"\nhttps://datapool.asf.alaska.edu/GRD_HD/SA/S1A_IW_GRDH_1SDV_20160128T120552_20160128T120617_009694_00E257_7FA4.zip:\n2018-08-16 22:40:41 ERROR 404: Not Found.\nTraceback (most recent call last):\n  File \"/mnt/s/seppo/commands/seppo_recipe_processor.py\", line 664, in processing\n    in_files = prepare_working_directory (args,tempdir)\n  File \"/mnt/s/seppo/commands/seppo_recipe_processor.py\", line 414, in prepare_working_directory\n    myfile=get_file(args.input,tempdir)\n  File \"/mnt/s/seppo/commands/seppo_recipe_processor.py\", line 327, in get_file\n    myfile=get_https(d_s,d_t='.')\n  File \"/mnt/s/seppo/commands/seppo_recipe_processor.py\", line 228, in get_https\n    raise RuntimeError('Could not retrieve {}'.format(d_s))\nRuntimeError: Could not retrieve https://datapool.asf.alaska.edu/GRD_HD/SA/S1A_IW_GRDH_1SDV_20160128T120552_20160128T120617_009694_00E257_7FA4.zip\n\nDuring handling of the above exception, another exception occurred:\n\nTraceback (most recent call last):\n  File \"/mnt/s/seppo/commands/seppo_recipe_processor.py\", line 764, in <module>\n    main()\n  File \"/mnt/s/seppo/commands/seppo_recipe_processor.py\", line 760, in main\n    return processing(args)\n  File \"/mnt/s/seppo/commands/seppo_recipe_processor.py\", line 666, in processing\n    raise RuntimeError(\"Error preparing recipe or input data {}\\n{}\".format(args.recipe,args.input))\nRuntimeError: Error preparing recipe or input data ${SEPPO_HOME}/recipies/gamma/recipe_sentinel1_grd.py -t -r\nhttps://datapool.asf.alaska.edu/GRD_HD/SA/S1A_IW_GRDH_1SDV_20160128T120552_20160128T120617_009694_00E257_7FA4.zip\n"
    },
    "Duration_hms": "0:00:06.598434",
    "Duration_sec": "6.598434",
    "EndTime": "2018-08-16T22:40:41.292113",
    "Job": "seppo_recipe_processor.py -z -o s3://data.earth/sar/sentinel1/rtc/20.0m -r '${SEPPO_HOME}/recipies/gamma/recipe_sentinel1_grd.py -t -r' -i https://datapool.asf.alaska.edu/GRD_HD/SA/S1A_IW_GRDH_1SDV_20160128T120552_20160128T120617_009694_00E257_7FA4.zip",
    "JobID": "sentinel1-scenes",
    "StartTime": "2018-08-16T22:40:34.693679",
    "User": "ebduser"
}
-----------------------------------------------------------
seppo_recipe_processor.py -z -o s3://data.earth/sar/sentinel1/rtc/20.0m -r '${SEPPO_HOME}/recipies/gamma/recipe_sentinel1_grd.py -t -r' -i https://datapool.asf.alaska.edu/GRD_HD/SA/S1A_IW_GRDH_1SDV_20160128T120552_20160128T120617_009694_00E257_7FA4.zip
-----------------------------------------------------------
